<?xml version="1.0" ?>
<mujoco>
    <compiler angle="radian" coordinate="local" inertiafromgeom="true"/>
    <default>
        <joint armature="0.1" damping="0.5" limited="true"/>
        <geom condim="1" contype="1" conaffinity="1" rgba="0.7 0.7 0.7 1"/>
        <motor ctrlrange="-1 1" ctrllimited="true" gear="100"/>
    </default>

    <option timestep="0.005" gravity="0 0 -9.81" integrator="RK4"/>

    <worldbody>
        <light diffuse=".5 .5 .5" pos="0 0 3" dir="0 0 -1"/>
        <camera name="track" pos="0 -3 0.3" mode="trackcom"/>
        <geom name="floor" type="plane" size="1 1 40" rgba=".6 .6 .6 1"/>
        
        <!-- 躯干 -->
        <body name="torso" pos="0 0 1.25">
            <joint name="root" type="free" limited="false"/>
            <geom name="torso" type="capsule" fromto="0 0 0 0 0 0.15" size="0.05" mass="10"/>
            
            <!-- 头部 -->
            <body name="head" pos="0 0 0.3">
                <joint name="neck" type="ball" pos="0 0 0" limited="true" range="0 0.5"/>
                <geom name="head" type="sphere" size="0.05" mass="5"/>
            </body>
            
            <!-- 左臂 -->
            <body name="left_arm" pos="0 0.1 0.2">
                <joint name="left_shoulder" type="ball" pos="0 0 0" limited="true" range="0 0.8"/>
                <geom name="left_upper_arm" type="capsule" fromto="0 0 0 0 0 -0.2" size="0.03" mass="3"/>
                <body name="left_forearm" pos="0 0 -0.2">
                    <joint name="left_elbow" type="hinge" axis="0 1 0" limited="true" range="-1.57 0"/>
                    <geom name="left_lower_arm" type="capsule" fromto="0 0 0 0 0 -0.2" size="0.02" mass="2"/>
                </body>
            </body>
            
            <!-- 右臂 -->
            <body name="right_arm" pos="0 -0.1 0.2">
                <joint name="right_shoulder" type="ball" pos="0 0 0" limited="true" range="0 0.8"/>
                <geom name="right_upper_arm" type="capsule" fromto="0 0 0 0 0 -0.2" size="0.03" mass="3"/>
                <body name="right_forearm" pos="0 0 -0.2">
                    <joint name="right_elbow" type="hinge" axis="0 1 0" limited="true" range="-1.57 0"/>
                    <geom name="right_lower_arm" type="capsule" fromto="0 0 0 0 0 -0.2" size="0.02" mass="2"/>
                </body>
            </body>
            
            <!-- 左腿 -->
            <body name="left_thigh" pos="0 0.1 0">
                <joint name="left_hip" type="ball" pos="0 0 0" limited="true" range="0 0.8"/>
                <geom name="left_thigh" type="capsule" fromto="0 0 0 0 0 -0.3" size="0.04" mass="8"/>
                <body name="left_shin" pos="0 0 -0.3">
                    <joint name="left_knee" type="hinge" axis="0 1 0" limited="true" range="-1.57 0"/>
                    <geom name="left_shin" type="capsule" fromto="0 0 0 0 0 -0.3" size="0.03" mass="6"/>
                    <body name="left_foot" pos="0 0 -0.3">
                        <joint name="left_ankle" type="ball" pos="0 0 0" limited="true" range="0 0.5"/>
                        <geom name="left_foot" type="capsule" fromto="0 0 0 0 0.1 0" size="0.03" mass="4"/>
                    </body>
                </body>
            </body>
            
            <!-- 右腿 -->
            <body name="right_thigh" pos="0 -0.1 0">
                <joint name="right_hip" type="ball" pos="0 0 0" limited="true" range="0 0.8"/>
                <geom name="right_thigh" type="capsule" fromto="0 0 0 0 0 -0.3" size="0.04" mass="8"/>
                <body name="right_shin" pos="0 0 -0.3">
                    <joint name="right_knee" type="hinge" axis="0 1 0" limited="true" range="-1.57 0"/>
                    <geom name="right_shin" type="capsule" fromto="0 0 0 0 0 -0.3" size="0.03" mass="6"/>
                    <body name="right_foot" pos="0 0 -0.3">
                        <joint name="right_ankle" type="ball" pos="0 0 0" limited="true" range="0 0.5"/>
                        <geom name="right_foot" type="capsule" fromto="0 0 0 0 0.1 0" size="0.03" mass="4"/>
                    </body>
                </body>
            </body>
        </body>
    </worldbody>

    <actuator>
        <!-- 头部控制 -->
        <motor joint="neck" gear="100"/>
        
        <!-- 左臂控制 -->
        <motor joint="left_shoulder" gear="100"/>
        <motor joint="left_elbow" gear="100"/>
        
        <!-- 右臂控制 -->
        <motor joint="right_shoulder" gear="100"/>
        <motor joint="right_elbow" gear="100"/>
        
        <!-- 左腿控制 -->
        <motor joint="left_hip" gear="100"/>
        <motor joint="left_knee" gear="100"/>
        <motor joint="left_ankle" gear="100"/>
        
        <!-- 右腿控制 -->
        <motor joint="right_hip" gear="100"/>
        <motor joint="right_knee" gear="100"/>
        <motor joint="right_ankle" gear="100"/>
    </actuator>
</mujoco> 